Workbook

Sheet Résumé de l’exportation
B3: Ce document a été exporté depuis Numbers. Chaque tableau a été converti en feuille de calcul Excel. Tous les autres objets sur chaque feuille Numbers ont été placés sur des feuilles de calcul différentes. Veuillez noter que les calculs de formules peuvent être différents dans Excel.
B7: Nom de la feuille Numbers | C7: Nom du tableau Numbers | D7: Nom de la feuille de calcul Excel
B9: Plan d'actions
C10: Tableau 1 | D10: Plan d'actions
B11: Programme
C12: Tableau 1 | D12: Programme
B13: Budget
C14: Budget | D14: Budget - Budget
C15: Dépenses réelles | D15: Budget - Dépenses réelles
B16: Invités
C17: Tableau 1 | D17: Invités
B18: Témoins & Honneurs
C19: Tableau 1 | D19: Témoins & Honneurs - Tableau 1
C20: Tableau 1-1 | D20: Témoins & Honneurs - Tableau 1-
B21: EVJF & EVG
C22: Léa | D22: EVJF & EVG - Léa
C23: PA | D23: EVJF & EVG - PA
B24: Lieu
C25: Tableau 1 | D25: Lieu
B26: Repas
C27: Tableau 1 | D27: Repas - Tableau 1
C28: Gauthier traiteur | D28: Repas - Gauthier traiteur
C29: Devis Food Truck | D29: Repas - Devis Food Truck
C30: Devis Brunch | D30: Repas - Devis Brunch
B31: Couchages
C32: Lodge | D32: Couchages - Lodge
C33: Maison | D33: Couchages - Maison
C34: Cabane | D34: Couchages - Cabane
C35: Tipis | D35: Couchages - Tipis
B36: Photos & Vidéos
C37: Tableau 1 | D37: Photos & Vidéos - Tableau 1
C38: Groupe photos | D38: Photos & Vidéos - Groupe photos
B39: Musique
C40: Tableau 1 | D40: Musique
B41: Activités
C42: Tableau 1 | D42: Activités - Tableau 1
C43: Devis Coordinatrice | D43: Activités - Devis Coordinatrice
B44: Habillement
C45: Tableau 1 | D45: Habillement
B46: Voiture
...

Sheet Plan d'actions
A1: Tâche | B1: ETA | C1: Responsable | D1: Statut
A2: Cocher les invités éligibles aux faire-part | B2: 46047 | C2: Léa GINTZ | D2: Terminé
A3: Cocher les invités éligibles aux faire-part | B3: 46047 | C3: Pierre-Alexandre COUBARD | D3: En cours
A4: Réserver les visites de lieux | B4: 46054 | C4: Léa GINTZ & Pierre-Alexandre COUBARD | D4: Terminé
A5: Faire un premier modèle de faire-part digital | B5: 46068 | C5: Léa GINTZ | D5: Terminé
A6: Rechercher les prestataires de brunch | B6: 46081 | C6: Léa GINTZ | D6: En cours
A7: Faire la liste des VIP | B7: 46081 | C7: Léa GINTZ & Pierre-Alexandre COUBARD | D7: Terminé
A8: Trouver église | B8: 46113 | C8: Léa GINTZ | D8: Terminé
A9: Remplir tableau invités (adresse, tel, mail) | B9: 46127 | C9: Léa GINTZ & Pierre-Alexandre COUBARD | D9: En cours
A10: Première ébauche programme | B10: 46127 | C10: Pierre-Alexandre COUBARD | D10: En cours
A11: Valider la répartition hébergements | B11: 46127 | C11: Pierre-Alexandre COUBARD | D11: En cours
A12: Finir le site internet | B12: 46142 | C12: Pierre-Alexandre COUBARD | D12: Non commencé
A13: Faire dossier mariage église | B13: 46169 | C13: Léa GINTZ | D13: En cours
... A43: Envoyer les remerciements à tous les invités | B43: 46629 | C43: Léa GINTZ | D43: Non commencé
A81: Tâches restantes | B81: {=COUNTA($C$2:$C$41)-COUNTIF($C$2:$C$41,"Terminé")} -> 40 | C81: Travail fait —> | D81: {=_xlfn.IFERROR(COUNTIF($D$2:$D$80,"Terminé")/COUNTA($D$2:$D$80),0%)} -> 0.23809524

Sheet Programme
A1: ORGANISATION
A2: Date | B2: Heure début | C2: Heure fin | D2: Activité | E2: Responsable | F2: Lieu | G2: Remarques
A3: Vendredi 13 août 2027 | B3: 08h00 | C3: 08h00 | D3: Récupération de la Porsche à Sartrouville | E3: PA | F3: Sartrouville
B4: 11h00 | C4: 11h30 | D4: Cérémonie civile — mairie | E4: Léa & PA | F4: Mairie de Sillé-le-Guillaume
B5: 11h30 | C5: 13h00 | D5: Déjeuner au restaurant | E5: TBD | F5: Sillé-le-Guillaume
B6: 13h00 | C6: 15h30 | D6: Route vers le Domaine de Meaucé | E6: PA | F6: Domaine de Meaucé
B7: 14h00 | C7: 14h00 | D7: Récupération du domaine | E7: Léa & PA | F7: Domaine de Meaucé
B8: 19h00 | C8: 22h00 | D8: Dîner Tarte Flambée | E8: Flamman | F8: Domaine de Meaucé
A9: Samedi 14 août 2027 | B9: TBF | C9: TBF | D9: Petit-déjeuner du samedi matin | E9: Domaine | F9: Domaine de Meaucé
B10: 08h30 | C10: 09h00 | D10: Arrivée coiffure / maquillage | E10: Coiffeuse & maquilleuse | F10: Domaine de Meaucé
B11: 09h00 | C11: 09h00 | D11: Arrivée de Tiphany — installation générale | E11: Tiphany + assistante | F11: Domaine de Meaucé
B12: 09h00 | C12: 12h30 | D12: Préparatifs Léa | E12: Léa, coiffeuse, témoins, photographe, vidéaste | F12: Domaine de Meaucé
B13: 09h00 | C13: 11h00 | D13: Préparatifs PA | E13: PA, témoins, photographe, vidéaste | F13: Domaine de Meaucé
B14: 12h00 | C14: 12h45 | D14: Déjeuner léger du samedi midi | E14: Libre | F14: Domaine de Meaucé
B15: 13h00 | C15: 13h00 | D15: Habillage final | E15: Léa & PA | F15: Domaine de Meaucé
B16: 13h30 | C16: 13h30 | D16: Départ vers l'église | E16: Chauffeur LRM | F16: Domaine → Église
B17: 13h30 | C17: 14h45 | D17: Accueil des invités à l'église | E17: Tiphany + assistante | F17: Église Saint-Pierre de Manou
B18: 14h45 | C18: 14h45 | D18: Arrivée de PA à l'église | E18: PA, Constance | F18: Église Saint-Pierre de Manou
B19: 46243.622 | C19: 46243.625 | D19: Arrivée de Léa à l'église | E19: Léa, Christophe G | F19: Église Saint-Pierre de Manou
B20: 15h00 | C20: 16h00 | D20: Cérémonie religieuse | F20: Église Saint-Pierre de Manou
B21: 16h00 | C21: 16h40 | D21: Sortie & photos de groupe prioritaires | E21: Photographe, vidéaste | F21: Église (parvis)
B22: 16h40 | C22: 46243.708 | D22: Retour vers le domaine
B23: 46243.708 | C23: 46243.729 | D23: Accueil soft par traiteur, installations pour ceux qui dorment sur place, photo pour Léa & PA | E23: Tiphany
B24: 46243.729 | C24: 46243.75 | D24: Photos | E24: Photographe, vidéaste
B25: 46243.75 | C25: 19h30 | D25: Vin d'honneur | E25: Traiteur, MV, Rachel Wong | F25: Domaine de Meaucé
B26: 19h30 | C26: 46243.833 | D26: Photos de groupe et passage a table | E26: Tiphany | F26: Domaine de Meaucé
B27: 20h00 | C27: 22h00 | D27: Dîner assis & discours | E27: Traiteur, famille, amis | F27: Domaine de Meaucé
B28: 46244.896 | C28: 46244.917 | D28: Changement de robe Léa
B29: 22h00 | C29: 22h05 | D29: Première danse | E29: DJ | F29: Domaine de Meaucé
B30: 22h05 | C30: 23h05 | D30: Concert live Seven Ages (1h) | E30: Seven Ages | F30: Domaine de Meaucé
B31: 23h05 | C31: 23h30 | D31: Dessert | E31: Traiteur | F31: Domaine de Meaucé
B32: 23h30 | C32: 04h00 | D32: Soirée dansante | E32: DJ | F32: Domaine de Meaucé
B33: 46243.188 | D33: Coupure de la musique | E33: DJ | F33: Domaine de Meaucé
B34: 04h00 | C34: 05h00 | D34: Fin de soirée | F34: Domaine de Meaucé
A35: Dimanche 15 août 2027 | B35: 09h00 | C35: 11h00 | D35: Petit-déjeuner | E35: Domaine (inclus) | F35: Domaine de Meaucé
B36: 11h00 | C36: 15h00 | D36: Pool party — piscine, brunch & DJ set | E36: DJ, traiteur brunch | F36: Domaine de Meaucé
B37: 15h00 | C37: 15h30 | D37: Temps libre & début du rangement | E37: Familles et témoins | F37: Domaine de Meaucé
B38: 15h30 | C38: 16h00 | D38: Check-out des tipis | E38: Invités des tipis | F38: Domaine de Meaucé
B39: 16h00 | C39: 16h30 | D39: Check-out du lodge | E39: Invités du lodge | F39: Domaine de Meaucé
B40: 16h30 | C40: 17h00 | D40: Check-out de la maison & fin piscine/salles | E40: Léa & PA | F40: Domaine de Meaucé
...

Sheet Budget - Budget
A1: Budget
A2: Catégorie | B2: Budget initial | C2: Budget révisé | D2: Delta | E2: Réel | F2: Delta
A3: Repas | B3: 12000 | C3: {='Repas - Tableau 1'!C$34} -> 16904.911 | D3: {=_xlfn.IFERROR(C3/B3-1,0)} -> 0.40874258 | E3: {=SUMIF('Budget - Dépenses réelles'!A3:A31,$A3,'Budget - Dépenses réelles'!D3:D31)} -> 284 | F3: {=_xlfn.IFERROR(E3/C3-1,0)} -> -0.98320015
A4: Réception | B4: 10000 | C4: {='Lieu'!M4} -> 13933.2 | D4: {=_xlfn.IFERROR(C4/B4-1,0)} -> 0.39332 | E4: {=SUMIF('Budget - Dépenses réelles'!A3:A31,$A4,'Budget - Dépenses réelles'!D3:D31)} -> 6000 | F4: {=_xlfn.IFERROR(E4/C4-1,0)} -> -0.56937387
A5: Habillement | B5: 2000 | C5: {='Habillement'!B$14} -> 7030 | D5: {=_xlfn.IFERROR(C5/B5-1,0)} -> 2.515 | E5: {=SUMIF('Budget - Dépenses réelles'!A3:A31,$A5,'Budget - Dépenses réelles'!D3:D31)} -> 0 | F5: {=_xlfn.IFERROR(E5/C5-1,0)} -> -1
A6: Lune de miel | B6: 10000 | C6: {='Lune de miel'!B$5} -> 5000 | D6: {=_xlfn.IFERROR(C6/B6-1,0)} -> -0.5 | E6: {=SUMIF('Budget - Dépenses réelles'!A3:A31,$A6,'Budget - Dépenses réelles'!D3:D31)} -> 0 | F6: {=_xlfn.IFERROR(E6/C6-1,0)} -> -1
A7: Musique | B7: 2000 | C7: {='Musique'!C$6} -> 3833.34 | D7: {=_xlfn.IFERROR(C7/B7-1,0)} -> 0.91667 | E7: {=SUMIF('Budget - Dépenses réelles'!A3:A31,$A7,'Budget - Dépenses réelles'!D3:D31)} -> 941 | F7: {=_xlfn.IFERROR(E7/C7-1,0)} -> -0.75452217
A8: Décoration | B8: 3000 | C8: {='Décorations - Tableau 1'!C$10} -> 2985.8 | D8: {=_xlfn.IFERROR(C8/B8-1,0)} -> -0.0047333333 | E8: {=SUMIF('Budget - Dépenses réelles'!A3:A31,$A8,'Budget - Dépenses réelles'!D3:D31)} -> 0 | F8: {=_xlfn.IFERROR(E8/C8-1,0)} -> -1
A9: Alliances | B9: 4000 | C9: {='Alliances'!B$6} -> 2430 | D9: {=_xlfn.IFERROR(C9/B9-1,0)} -> -0.3925 | E9: {=SUMIF('Budget - Dépenses réelles'!A3:A31,$A9,'Budget - Dépenses réelles'!D3:D31)} -> 0 | F9: {=_xlfn.IFERROR(E9/C9-1,0)} -> -1
A10: Activités | B10: 1000 | C10: {='Activités - Tableau 1'!B$8} -> 2209 | D10: {=_xlfn.IFERROR(C10/B10-1,0)} -> 1.209 | E10: {=SUMIF('Budget - Dépenses réelles'!A3:A31,$A10,'Budget - Dépenses réelles'!D3:D31)} -> 479.6 | F10: {=_xlfn.IFERROR(E10/C10-1,0)} -> -0.78288818
A11: Photos & Vidéos | B11: 2500 | C11: {='Photos & Vidéos - Tableau 1'!C$5} -> 2117 | D11: {=_xlfn.IFERROR(C11/B11-1,0)} -> -0.1532 | E11: {=SUMIF('Budget - Dépenses réelles'!A3:A31,$A11,'Budget - Dépenses réelles'!D3:D31)} -> 106 | F11: {=_xlfn.IFERROR(E11/C11-1,0)} -> -0.94992915
A12: Voiture | B12: 500 | C12: {='Voiture'!C$4} -> 1250 | D12: {=_xlfn.IFERROR(C12/B12-1,0)} -> 1.5 | E12: {=SUMIF('Budget - Dépenses réelles'!A3:A31,$A12,'Budget - Dépenses réelles'!D3:D31)} -> 190 | F12: {=_xlfn.IFERROR(E12/C12-1,0)} -> -0.848
A13: Coiffure et maquillage | B13: 1500 | C13: {='Coiffure_Maquillage - Devis Mak'!C8} -> 830 | D13: {=_xlfn.IFERROR(C13/B13-1,0)} -> -0.44666667 | E13: {=SUMIF('Budget - Dépenses réelles'!A3:A31,$A13,'Budget - Dépenses réelles'!D3:D31)} -> 0 | F13: {=_xlfn.IFERROR(E13/C13-1,0)} -> -1
A14: Cérémonie religieuse | B14: 600 | C14: 700 | D14: {=_xlfn.IFERROR(C14/B14-1,0)} -> 0.16666667 | E14: {=SUMIF('Budget - Dépenses réelles'!A3:A31,$A14,'Budget - Dépenses réelles'!D3:D31)} -> 0 | F14: {=_xlfn.IFERROR(E14/C14-1,0)} -> -1
A15: Cérémonie mairie | B15: 500 | C15: 500 | D15: {=_xlfn.IFERROR(C15/B15-1,0)} -> 0 | E15: {=SUMIF('Budget - Dépenses réelles'!A3:A31,$A15,'Budget - Dépenses réelles'!D3:D31)} -> 0 | F15: {=_xlfn.IFERROR(E15/C15-1,0)} -> -1
A16: Notaire | B16: 500 | C16: {='Notaire'!B$6} -> 378.98 | D16: {=_xlfn.IFERROR(C16/B16-1,0)} -> -0.24204 | E16: {=SUMIF('Budget - Dépenses réelles'!A3:A31,$A16,'Budget - Dépenses réelles'!D3:D31)} -> 0 | F16: {=_xlfn.IFERROR(E16/C16-1,0)} -> -1
A17: Cadeaux | B17: -5000 | C17: -5000 | D17: {=_xlfn.IFERROR(C17/B17-1,0)} -> 0 | E17: {=SUMIF('Budget - Dépenses réelles'!A3:A31,$A17,'Budget - Dépenses réelles'!D3:D31)} -> 0 | F17: {=_xlfn.IFERROR(E17/D17-1,0)} -> 0
A18: Total | B18: {=SUM(B3:B17)} -> 45100 | C18: {=SUM(C3:C17)} -> 55102.231 | D18: {=_xlfn.IFERROR(C18/B18-1,0)} -> 0.22177896 | E18: {=SUM(E3:E17)} -> 8000.6 | F18: {=_xlfn.IFERROR(E18/C18-1,0)} -> -0.85480443

Sheet Budget - Dépenses réelles
A1: Dépenses réelles
A2: Catégorie | B2: Description | C2: Date | D2: Montant | E2: Payeur
A3: Voiture | B3: Acompte LRM | C3: 45937 | D3: 190 | E3: PA
A4: Réception | B4: Acompte 1 | C4: 46107 | D4: 2000 | E4: Léa & PA
A5: Musique | B5: Acompte Maison Groovy | C5: 46133 | D5: 762 | E5: Léa & PA
A6: Activités | B6: Acompte Live Painting | C6: 46139 | D6: 100 | E6: Léa & PA
A7: Musique | B7: Acompte Seven Ages | C7: 46139 | D7: 55 | E7: Léa & PA
A8: Photos & Vidéos | B8: Acompte photographe | C8: 46140 | D8: 106 | E8: Léa & PA
A9: Réception | B9: Acompte 2 | C9: 46235 | D9: 4000 | E9: Léa & PA
A10: Musique | B10: Acompte MV | C10: 46240 | D10: 124 | E10: Léa & PA
A11: Activités | B11: Acompte Wedding Planner | C11: 46241 | D11: 379.6 | E11: Léa & PA
A12: Repas | B12: Acompte Flamm’Mann | C12: 46248 | D12: 284 | E12: Léa & PA
D32: {=SUM(D3:D31)} -> 8000.6

Sheet Invités
A1: Statut | B1: Nom | C1: Prénom | D1: Groupe | E1: Catégorie | F1: Adresse postale | G1: Adresse email | H1: Portable | I1: Faire-part digital | J1: Faire-part | K1: Confirmation | L1: Mairie | M1: Soirée accueil | N1: Église | O1: Repas | P1: Couchage | Q1: Placé couchage | R1: Alcool | S1: Brunch | T1: VIP | U1: Végétarien | V1: Témoins & Honneurs | W1: Lien
A2: Traité | B2: GINTZ | C2: Léa | D2: Mariés | E2: Adulte
A3: Traité | B3: COUBARD | C3: Pierre-Alexandre | D3: Mariés | E3: Adulte
A4: Traité | B4: GINTZ | C4: Christophe | D4: Famille Léa | E4: Adulte | F4: 66 rue de Saverne, 67370 Neugartheim-Ittlenheim | H4: 07 69 06 33 72 | I4: TRUE | J4: TRUE | K4: TRUE | L4: TRUE | M4: TRUE | N4: TRUE | O4: TRUE | P4: TRUE | Q4: TRUE | R4: TRUE | S4: TRUE | T4: TRUE | U4: FALSE | V4: FALSE | W4: Père Léa
A5: Traité | B5: GINTZ | C5: Alena | D5: Famille Léa | E5: Adulte | H5: 06 31 58 69 45 | I5: TRUE | J5: FALSE | K5: TRUE | L5: TRUE | M5: TRUE | N5: TRUE | O5: TRUE | P5: TRUE | Q5: TRUE | R5: FALSE | S5: TRUE | T5: TRUE | U5: FALSE | V5: FALSE | W5: Mère Léa
A6: Traité | B6: GINTZ | C6: Romain | D6: Famille Léa | E6: Adulte | H6: 07 68 68 22 01 | I6: TRUE | J6: FALSE | K6: TRUE | L6: TRUE | M6: TRUE | N6: TRUE | O6: TRUE | P6: TRUE | Q6: TRUE | R6: TRUE | S6: TRUE | T6: TRUE | U6: FALSE | V6: TRUE | W6: Frère Léa
A7: Traité | B7: GINTZ | C7: Amélie | D7: Famille Léa | E7: Adulte | H7: 07 66 87 23 25 | I7: TRUE | J7: FALSE | K7: TRUE | L7: TRUE | M7: TRUE | N7: TRUE | O7: TRUE | P7: TRUE | Q7: TRUE | R7: TRUE | S7: TRUE | T7: TRUE | U7: FALSE | V7: TRUE | W7: Soeur Léa
A8: En cours | B8: GINTZ | C8: Christianne | D8: Famille Léa | E8: Adulte | F8: 8 Rue de L’Église, 67370 Behlenheim-Truchtersheim | H8: 07 67 45 63 14 | I8: TRUE | J8: TRUE | K8: FALSE | L8: FALSE | M8: FALSE | N8: FALSE | O8: FALSE | P8: FALSE | Q8: FALSE | R8: FALSE | S8: FALSE | T8: FALSE | U8: FALSE | V8: FALSE | W8: Grand-mère Léa du cote de son père
A9: En cours | B9: GINTZ | C9: Michel | D9: Famille Léa | E9: Adulte | I9: TRUE | J9: FALSE | K9: FALSE | L9: FALSE | M9: FALSE | N9: FALSE | O9: FALSE | P9: FALSE | Q9: FALSE | R9: FALSE | S9: FALSE | T9: FALSE | U9: FALSE | V9: FALSE | W9: GRand-père Léa du cote de son pere
A10: Traité | B10: ZINCK | C10: Gaspard | D10: Famille Léa | E10: Adulte | H10: 07 67 80 36 70 | I10: TRUE | J10: FALSE | K10: TRUE | L10: TRUE | M10: TRUE | N10: TRUE | O10: TRUE | P10: TRUE | Q10: TRUE | R10: TRUE | S10: TRUE | T10: TRUE | U10: FALSE | V10: FALSE | W10: Copain d’Amélie la soeur de lléa
A11: En cours | B11: HABOUZIT | C11: Mélissande | D11: Famille Léa | E11: Adulte | H11: 06 38 36 15 46 | I11: TRUE | J11: FALSE | K11: TRUE | L11: TRUE | M11: TRUE | N11: TRUE | O11: TRUE | P11: TRUE | Q11: TRUE | R11: TRUE | S11: TRUE | T11: TRUE | U11: FALSE | V11: FALSE | W11: Copien de Romain frère de lea
A12: En cours | B12: BURANOVSKA | C12: Elisabeth | D12: Famille Léa | E12: Adulte | F12: Babka Buranovska Alzbeta Svabska 78 Presov 08001 République Slovaque | I12: TRUE | J12: TRUE | K12: FALSE | L12: FALSE | M12: FALSE | N12: FALSE | O12: FALSE | P12: FALSE | Q12: FALSE | R12: FALSE | S12: FALSE | T12: FALSE | U12: FALSE | V12: FALSE | W12: GRand mère de Léa du coté de sa mere
A13: En cours | B13: TKACOVY | C13: Jozef | D13: Famille Léa | E13: Adulte | F13: Jozef Tkac Podhradik 109 Podhradik 08006 République Slovaque | H13: +42 19 18 96 87 70 | I13: TRUE | J13: TRUE | K13: FALSE | L13: FALSE | M13: TRUE | N13: TRUE | O13: TRUE | P13: TRUE | Q13: TRUE | R13: TRUE | S13: TRUE | T13: FALSE | U13: FALSE | V13: FALSE | W13: ami du père de lea
A14: En cours | B14: TKACOVA | C14: Marta | D14: Famille Léa | E14: Adulte | I14: TRUE | J14: FALSE | K14: FALSE | L14: FALSE | M14: TRUE | N14: TRUE | O14: TRUE | P14: TRUE | Q14: TRUE | R14: FALSE | S14: TRUE | T14: FALSE | U14: FALSE | V14: FALSE | W14: Femme de Josef
A15: Traité | B15: GINTZ | C15: Laurence | D15: Famille Léa | E15: Adulte | F15: 1 rue des Acacias, 67270 Gougenheim | H15: 06 86 65 32 67 | I15: TRUE | J15: TRUE | K15: TRUE | L15: TRUE | M15: TRUE | N15: TRUE | O15: TRUE | P15: TRUE | Q15: TRUE | R15: FALSE | S15: TRUE | T15: TRUE | U15: FALSE | V15: FALSE | W15: Mariane de lea
A16: Traité | B16: GINTZ | C16: Marc | D16: Famille Léa | E16: Adulte | H16: 07 85 29 27 40 | I16: TRUE | J16: FALSE | K16: TRUE | L16: TRUE | M16: TRUE | N16: TRUE | O16: TRUE | P16: TRUE | Q16: TRUE | R16: TRUE | S16: TRUE | T16: TRUE | U16: FALSE | V16: FALSE | W16: Marie de Laurence Gintz
A17: Traité | B17: HILD | C17: Valérie | D17: Famille Léa | E17: Adulte | F17: 3 rue des Tilleuls, 67270 Gougenheim | H17: 06 38 60 61 69 | I17: TRUE | J17: TRUE | K17: TRUE | L17: TRUE | M17: TRUE | N17: TRUE | O17: TRUE | P17: TRUE | Q17: TRUE | R17: FALSE | S17: TRUE | T17: TRUE | U17: FALSE | V17: FALSE | W17: Soeur de la marraine de lea
A18: Traité | B18: JOURNOT | C18: Daniel | D18: Famille Léa | E18: Adulte | H18: 07 68 66 21 86 | I18: TRUE | J18: FALSE | K18: TRUE | L18: TRUE | M18: TRUE | N18: TRUE | O18: TRUE | P18: TRUE | Q18: TRUE | R18: TRUE | S18: TRUE | T18: TRUE | U18: FALSE | V18: FALSE | W18: Mari de Valérie
A19: En cours | B19: GINTZ | C19: Régis | D19: Famille Léa | E19: Adulte | F19: 11 rue kobler 67370 Dingsheim | H19: 06 70 21 98 92 | I19: TRUE | J19: TRUE | K19: FALSE | L19: FALSE | M19: TRUE | N19: TRUE | O19: TRUE | P19: TRUE | Q19: TRUE | R19: TRUE | S19: TRUE | T19: FALSE | U19: FALSE | V19: FALSE | W19: Oncle de lea du octe de osn pere
A20: En cours | B20: GINTZ | C20: Linda | D20: Famille Léa | E20: Adulte | H20: 06 86 14 57 57 | I20: TRUE | J20: FALSE | K20: FALSE | L20: FALSE | M20: TRUE | N20: TRUE | O20: TRUE | P20: TRUE | Q20: TRUE | R20: FALSE | S20: TRUE | T20: FALSE | U20: FALSE | V20: FALSE | W20: Femme de de regis G
A21: En cours | B21: GINTZ | C21: Vincent | D21: Famille Léa | E21: Adulte | F21: 6 rue de la forge 67370 behlenheim | H21: 06 12 51 56 99 | I21: TRUE | J21: TRUE | K21: FALSE | L21: FALSE | M21: TRUE | N21: TRUE | O21: TRUE | P21: TRUE | Q21: TRUE | R21: TRUE | S21: TRUE | T21: FALSE | U21: FALSE | V21: FALSE | W21: Oncle de lea du coté de son pere
A22: En cours | B22: GINTZ | C22: Joëlle | D22: Famille Léa | E22: Adulte | I22: TRUE | J22: FALSE | K22: FALSE | L22: FALSE | M22: TRUE | N22: TRUE | O22: TRUE | P22: TRUE | Q22: TRUE | R22: FALSE | S22: TRUE | T22: FALSE | U22: FALSE | V22: FALSE | W22: Femme de Vincent G
A23: En cours | B23: KIEFFER | C23: Jean-Marc | D23: Famille Léa | E23: Adulte | F23: 10 rue des Roses, 67370 Behlenheim-Truchtersheim | I23: TRUE | J23: TRUE | K23: FALSE | L23: FALSE | M23: TRUE | N23: TRUE | O23: TRUE | P23: TRUE | Q23: TRUE | R23: TRUE | S23: TRUE | T23: FALSE | U23: FALSE | V23: FALSE | W23: ami du père de lea
A24: En cours | B24: KIEFFER | C24: Marie | D24: Famille Léa | E24: Adulte | H24: 06 64 16 62 06 | I24: TRUE | J24: FALSE | K24: FALSE | L24: FALSE | M24: TRUE | N24: TRUE | O24: TRUE | P24: TRUE | Q24: TRUE | R24: TRUE | S24: TRUE | T24: FALSE | U24: FALSE | V24: FALSE | W24: Femme de JM Kieffer
A25: En cours | B25: MEYER | C25: Jeanne | D25: Famille Léa | E25: Adulte | H25: 06 29 09 36 12 | I25: TRUE | J25: TRUE | K25: FALSE | L25: FALSE | M25: FALSE | N25: FALSE | O25: FALSE | P25: FALSE | Q25: FALSE | R25: FALSE | S25: FALSE | T25: FALSE | U25: FALSE | V25: FALSE | W25: Soeur de la grand mere de Léa Chrisitnane G
A26: En cours | B26: MEYER | C26: Gilbert | D26: Famille Léa | E26: Adulte | I26: TRUE | J26: FALSE | K26: FALSE | L26: FALSE | M26: FALSE | N26: FALSE | O26: FALSE | P26: FALSE | Q26: FALSE | R26: FALSE | S26: FALSE | T26: FALSE | U26: FALSE | V26: FALSE | W26: Mari de Jeanne MEYER
A27: Traité | B27: GIANNIKAS | C27: Leonidas | D27: Amis Léa | E27: Adulte | H27: 06 50 66 07 59 | I27: TRUE | J27: FALSE | K27: TRUE | L27: TRUE | M27: TRUE | N27: TRUE | O27: TRUE | P27: TRUE | Q27: TRUE | R27: TRUE | S27: TRUE | T27: TRUE | U27: FALSE | V27: FALSE | W27: Meilleur ami de Romain G
A28: En cours | B28: CLAUDON | C28: Clémence | D28: Amis Léa | E28: Adulte | H28: 06 51 89 01 85 | I28: TRUE | J28: FALSE | K28: FALSE | L28: FALSE | M28: TRUE | N28: TRUE | O28: TRUE | P28: TRUE | Q28: TRUE | R28: TRUE | S28: TRUE | T28: FALSE | U28: FALSE | V28: FALSE | W28: Amie de Lea
A29: En cours | B29: NEITER | C29: Loanne | D29: Amis Léa | E29: Adulte | H29: 06 87 47 87 68 | I29: TRUE | J29: TRUE | K29: TRUE | L29: TRUE | M29: TRUE | N29: TRUE | O29: TRUE | P29: TRUE | Q29: TRUE | R29: TRUE | S29: TRUE | T29: TRUE | U29: FALSE | V29: TRUE | W29: Amie de Lea
A30: En cours | C30: Armand | D30: Amis Léa | E30: Adulte | H30: 07 82 24 14 29 | I30: TRUE | J30: FALSE | K30: TRUE | L30: TRUE | M30: TRUE | N30: TRUE | O30: TRUE | P30: TRUE | Q30: TRUE | R30: TRUE | S30: TRUE | T30: TRUE | U30: FALSE | V30: FALSE | W30: Copain de Loanne Neiter
A31: En cours | B31: RASANAYAGAM | C31: Marjorie | D31: Amis Léa | E31: Adulte | H31: 06 58 21 24 63 | I31: TRUE | J31: TRUE | K31: TRUE | L31: TRUE | M31: TRUE | N31: TRUE | O31: TRUE | P31: TRUE | Q31: TRUE | R31: TRUE | S31: TRUE | T31: TRUE | U31: FALSE | V31: TRUE | W31: Amie de Lea
A32: En cours | B32: GRISEVIC | C32: Leya | D32: Amis Léa | E32: Adulte | H32: 06 95 28 35 29 | I32: TRUE | J32: TRUE | K32: TRUE | L32: TRUE | M32: TRUE | N32: TRUE | O32: TRUE | P32: TRUE | Q32: TRUE | R32: TRUE | S32: TRUE | T32: TRUE | U32: FALSE | V32: TRUE | W32: Amie de Lea
A33: En cours | B33: KAYEMBE | C33: Audrey | D33: Amis Léa | E33: Adulte | H33: 06 60 48 09 19 | I33: TRUE | J33: FALSE | K33: FALSE | L33: FALSE | M33: FALSE | N33: TRUE | O33: TRUE | P33: TRUE | Q33: TRUE | R33: TRUE | S33: TRUE | T33: FALSE | U33: FALSE | V33: FALSE | W33: Amie de Lea
A34: En cours | B34: ANGOT | C34: Gabrielle | D34: Amis Léa | E34: Adulte | G34: gabrielle.angot@gmail.com | H34: 06 23 67 42 40 | I34: TRUE | J34: FALSE | K34: FALSE | L34: FALSE | M34: FALSE | N34: TRUE | O34: TRUE | P34: TRUE | Q34: TRUE | R34: TRUE | S34: TRUE | T34: FALSE | U34: FALSE | V34: FALSE | W34: Amie de Lea
A35: En cours | B35: BERTRAND | C35: Louise | D35: Amis Léa | E35: Adulte | G35: louisebertrand123@gmail.com | H35: 06 51 44 69 10 | I35: TRUE | J35: TRUE | K35: TRUE | L35: TRUE | M35: TRUE | N35: TRUE | O35: TRUE | P35: TRUE | Q35: TRUE | R35: TRUE | S35: TRUE | T35: TRUE | U35: FALSE | V35: TRUE | W35: Amie de Lea
A36: En cours | B36: AMBARTSONOVA | C36: Naza | D36: Amis Léa | E36: Adulte | G36: naza31072001@gmail.com | H36: 06 95 03 50 64 | I36: TRUE | J36: FALSE | K36: FALSE | L36: FALSE | M36: FALSE | N36: TRUE | O36: TRUE | P36: TRUE | Q36: TRUE | R36: FALSE | S36: TRUE | T36: FALSE | U36: FALSE | V36: FALSE | W36: Amie de Lea
A37: En cours | B37: COUBARD | C37: Christophe | D37: Famille PA | E37: Adulte | F37: 20 Rue Du Docteur Touchard 72140 Sillé Le Guillaume France | I37: TRUE | J37: TRUE | K37: TRUE | L37: TRUE | M37: TRUE | N37: TRUE | O37: TRUE | P37: TRUE | Q37: TRUE | R37: TRUE | S37: TRUE | T37: TRUE | U37: FALSE | V37: FALSE | W37: Pere de PA
A38: En cours | B38: MAGALHAES | C38: Luis | D38: Famille PA | E38: Adulte | I38: TRUE | J38: FALSE | K38: TRUE | L38: TRUE | M38: TRUE | N38: TRUE | O38: TRUE | P38: TRUE | Q38: TRUE | R38: TRUE | S38: TRUE | T38: TRUE | U38: FALSE | V38: FALSE | W38: Mari de Chrisitphe C et beau-père de PA
A39: En cours | B39: COUBARD | C39: Constance | D39: Famille PA | E39: Adulte | F39: 12 Rue de l’Université de Chicago 97300 CAYENNE | I39: TRUE | J39: TRUE | K39: TRUE | L39: TRUE | M39: TRUE | N39: TRUE | O39: TRUE | P39: TRUE | Q39: TRUE | R39: TRUE | S39: TRUE | T39: TRUE | U39: FALSE | V39: FALSE | W39: Mere de PA
A40: En cours | B40: LORENTE | C40: Hugues | D40: Famille PA | E40: Adulte | I40: TRUE | J40: FALSE | K40: TRUE | L40: TRUE | M40: TRUE | N40: TRUE | O40: TRUE | P40: TRUE | Q40: TRUE | R40: TRUE | S40: TRUE | T40: TRUE | U40: FALSE | V40: FALSE | W40: Mari de Constance C et beau père de PA
...

Sheet Témoins & Honneurs - Tableau 1
A1: Témoins | B1: Église | C1: Mairie
A2: Léa
A3: 1 | B3: Amélie | C3: Amélie
A4: 2 | B4: Romain | C4: Romain
A5: PA
A6: 1 | B6: Séverine | C6: Séverine
A7: 2 | B7: Maximilien | C7: Maximilien

Sheet Témoins & Honneurs - Tableau 1-
A1: Honneurs | B1: Nom | C1: Rôle
A2: Léa
A3: 1 | B3: Séverine
A4: 2 | B4: Amélie
A5: 3 | B5: Marjorie
A6: 4 | B6: Loanne
A7: 5 | B7: Louise | C7: EVJF
A8: 6 | B8: Leya
A9: PA
A10: 1 | B10: Alexandre | C10: EVG
A11: 2 | B11: Yoann | C11: Costume
A12: 3 | B12: Bilel
A13: 4 | B13: Luke
A14: 5 | B14: Maximilien
A15: 6 | B15: Tonton Théo

Sheet EVJF & EVG - Léa
A1: Léa
A2: Liste
A3: Léa
A4: Marjorie
A5: Louise
A6: Loanne
A7: Leya
A8: Amelie
A9: Severine
A10: Audrey
A11: Gabrielle
A12: Naza
... A14: Melissande

Sheet EVJF & EVG - PA
A1: PA
A2: Liste
A3: PA
A4: Alexandre
A5: Bilel
A6: Yoann
A7: Luke
A8: Olivier
A9: Jordan
A10: Goulven

Sheet Lieu
B2: Nom | C2: Prise de contact ? | D2: Retour ? | E2: Ok ? | F2: Pref Léa | G2: Lien | H2: Adresse | I2: Distance Paris | J2: Distance Paris | K2: Prix location | L2: Prix logements | M2: Total | N2: Nb jours de location | O2: Infos | P2: Traiteur imposé ? | Q2: Eglise dans le domaine | R2: Nombre d’invités (debout) | S2: Nombre d’invités (assis) | T2: Nombre de chambre | U2: Nombre de couchages | V2: Piscine | W2: Notes | X2: A visiter
B3: Domaine de Guerquesalle | C3: TRUE | D3: TRUE | E3: TRUE | F3: TRUE | G3: https://www.mariages.net/domaine-mariage/domaine-de-guerquesalle--e143600 | H3: Ferme de Guerquesalle 27140 Amécourt (Eure) | I3: 1h15 | J3: 1.25 | K3: 6400 | L3: 3500 | M3: {=_xlfn.IFERROR(K3+L3,50000)} -> 9900 | N3: 3 | O3: du vendredi 17h au dimanche 17h | P3: Non | Q3: Non | R3: 300 | S3: 220 | T3: 16 | U3: 40 | V3: Non | W3: {=IF(J3<2.1,1,0)+IF(M3<'Budget - Budget'!$C$3,2,0)+IF(S3<'Invités'!$B$91,0,1)+IF(U3>'Invités'!$P$91,2,0)+IF(V3="Non",0,1)+IF(Q3="Oui",1,0)+IF(P3="Non",2,0)+IF(N3>2,2,0)+IF(M3>15000,-2,0)} -> 8 | X3: TRUE
B4: Domaine de Meaucé | C4: TRUE | D4: TRUE | E4: TRUE | F4: TRUE | G4: https://www.mariages.net/domaine-mariage/domaine-de-meauce--e168716 | H4: La Grand' Maison 28240 Meaucé (Eure-et-Loir) | I4: 1h50 | J4: 1.83 | K4: 10800 | L4: 3000 | M4: {=_xlfn.IFERROR(K4+L4,50000)+((0.9*2)*'Invités'!P$91)} -> 13933.2 | N4: 3 | O4: vendredi midi au dimanche 18h | P4: Oui | Q4: Non | R4: 150 | S4: 150 | T4: 31 | U4: 86 | V4: Oui | W4: {=IF(J4<2.1,1,0)+IF(M4<'Budget - Budget'!$C$3,2,0)+IF(S4<'Invités'!$B$91,0,1)+IF(U4>'Invités'!$P$91,2,0)+IF(V4="Non",0,1)+IF(Q4="Oui",1,0)+IF(P4="Non",2,0)+IF(N4>2,2,0)+IF(M4>15000,-2,0)} -> 9 | X4: TRUE
B5: Domaine des Libellules | C5: TRUE | D5: TRUE | E5: TRUE | F5: FALSE | G5: https://www.mariages.net/domaine-mariage/domaine-des-libellules--e386935 | H5: Domaine des Libellules - La Chaise 28800 Bonneval (Eure-et-Loir) | I5: 2h | J5: 2 | K5: {=7800+420} -> 8220 | L5: 7848 | M5: {=_xlfn.IFERROR(K5+L5,50000)} -> 16068 | N5: 3 | O5: Vendredi 11h00 au dimanche 17h00 | P5: Non | Q5: Non | R5: 150 | S5: 150 | T5: 23 | U5: 68 | V5: Oui | W5: {=IF(J5<2.1,1,0)+IF(M5<'Budget - Budget'!$C$3,2,0)+IF(S5<'Invités'!$B$91,0,1)+IF(U5>'Invités'!$P$91,2,0)+IF(V5="Non",0,1)+IF(Q5="Oui",1,0)+IF(P5="Non",2,0)+IF(N5>2,2,0)+IF(M5>15000,-2,0)} -> 7 | X5: TRUE
B6: Le Saint Leonard | C6: TRUE | D6: TRUE | E6: TRUE | F6: FALSE | G6: https://www.mariages.net/domaine-mariage/le-saint-leonard--e358295 | H6: 4, Impasse du Prieure 77151 Montceaux-lès-Provins (Seine-et-Marne) | I6: 2h | J6: 2 | K6: 5400 | L6: 700 | M6: {=_xlfn.IFERROR(K6+L6,50000)} -> 6100 | N6: 3 | O6: vendredi après midi au dimanche 17h | P6: Non | Q6: Oui | R6: 250 | S6: 250 | T6: 8 | U6: 25 | V6: Non | W6: {=IF(J6<2.1,1,0)+IF(M6<'Budget - Budget'!$C$3,2,0)+IF(S6<'Invités'!$B$91,0,1)+IF(U6>'Invités'!$P$91,2,0)+IF(V6="Non",0,1)+IF(Q6="Oui",1,0)+IF(P6="Non",2,0)+IF(N6>2,2,0)+IF(M6>15000,-2,0)} -> 9 | X6: FALSE
B7: Vaumonteuil | C7: TRUE | D7: TRUE | E7: TRUE | F7: TRUE | G7: https://www.mariages.net/domaine-mariage/vaumonteuil--e247147 | H7: 14, Rue du Pont Kennedy 28240 Belhomert-Guéhouville (Eure-et-Loir) | I7: 1h45 | J7: 1.75 | K7: 7900 | L7: 0 | M7: {=_xlfn.IFERROR(K7+L7,50000)} -> 7900 | N7: 3 | O7: du vendredi 14h au dimanche 17h | P7: Non | Q7: Non | R7: 180 | S7: 180 | T7: 12 | U7: 27 | V7: Oui | W7: {=IF(J7<2.1,1,0)+IF(M7<'Budget - Budget'!$C$3,2,0)+IF(S7<'Invités'!$B$91,0,1)+IF(U7>'Invités'!$P$91,2,0)+IF(V7="Non",0,1)+IF(Q7="Oui",1,0)+IF(P7="Non",2,0)+IF(N7>2,2,0)+IF(M7>15000,-2,0)} -> 9 | X7: FALSE
B8: Domaine des Bayettes | C8: TRUE | D8: TRUE | E8: FALSE | G8: https://www.mariages.net/domaine-mariage/domaine-des-bayettes--e303720 | H8: 10, Route Nationale 78980 Mondreville (Yvelines) | I8: 1h | J8: 1 | K8: 9900 | L8: 0 | M8: {=_xlfn.IFERROR(K8+L8,50000)} -> 9900 | N8: 3 | O8: du vendredi 15h00 au dimanche 17h00 | P8: Non | Q8: Non | R8: 150 | S8: 150 | T8: 6 | U8: 22 | V8: Oui | W8: {=IF(J8<2.1,1,0)+IF(M8<'Budget - Budget'!$C$3,2,0)+IF(S8<'Invités'!$B$91,0,1)+IF(U8>'Invités'!$P$91,2,0)+IF(V8="Non",0,1)+IF(Q8="Oui",1,0)+IF(P8="Non",2,0)+IF(N8>2,2,0)+IF(M8>15000,-2,0)} -> 9 | X8: FALSE
B9: La Grange des Triplés | C9: TRUE | D9: TRUE | E9: TRUE | F9: FALSE | G9: https://www.mariages.net/domaine-mariage/la-grange-des-triples--e148536 | H9: 67, Route des Andelys 27150 Boisemont (Eure) | I9: 1h15 | J9: 1.25 | K9: 4900 | L9: {=780*2} -> 1560 | M9: {=_xlfn.IFERROR(K9+L9,50000)} -> 6460 | N9: 3 | O9: du vendredi 14h à dimanche fin d'après-midi | P9: Non | Q9: Non | R9: 220 | S9: 180 | T9: 2 gîtes | U9: 38 | V9: Non | W9: {=IF(J9<2.1,1,0)+IF(M9<'Budget - Budget'!$C$3,2,0)+IF(S9<'Invités'!$B$91,0,1)+IF(U9>'Invités'!$P$91,2,0)+IF(V9="Non",0,1)+IF(Q9="Oui",1,0)+IF(P9="Non",2,0)+IF(N9>2,2,0)+IF(M9>15000,-2,0)} -> 8 | X9: FALSE
B10: Château Amecourt | C10: TRUE | D10: TRUE | E10: TRUE | F10: FALSE | G10: https://www.mariages.net/chateau-mariage/chateau-amecourt--e136220 | H10: 2, Rue du Buisson de Bleu 27140 Amécourt (Eure) | I10: 1h20 | J10: 1.33 | K10: 4800 | L10: 2870 | M10: {=_xlfn.IFERROR(K10+L10,50000)} -> 7670 | N10: 3 | O10: du vendredi 18h au dimanche 17h | P10: Non | Q10: Non | R10: 130 | S10: 130 | T10: 16 | U10: 40 | V10: Oui | W10: {=IF(J10<2.1,1,0)+IF(M10<'Budget - Budget'!$C$3,2,0)+IF(S10<'Invités'!$B$91,0,1)+IF(U10>'Invités'!$P$91,2,0)+IF(V10="Non",0,1)+IF(Q10="Oui",1,0)+IF(P10="Non",2,0)+IF(N10>2,2,0)+IF(M10>15000,-2,0)} -> 9 | X10: FALSE
B11: Le Château de Motteux | C11: TRUE | D11: TRUE | E11: TRUE | F11: FALSE | G11: https://www.mariages.net/chateau-mariage/le-chateau-de-motteux--e195221 | H11: Château de Motteux 77130 Marolles-sur-Seine (Seine-et-Marne) | I11: 1h45 | J11: 1.75 | K11: 5500 | L11: 2450 | M11: {=_xlfn.IFERROR(K11+L11,50000)} -> 7950 | N11: 3 | O11: Vendredi 17h00 au dimanche 15h00 | P11: Non | Q11: Non | R11: 340 | S11: 200 | T11: 9 | U11: 45 | V11: Non | W11: {=IF(J11<2.1,1,0)+IF(M11<'Budget - Budget'!$C$3,2,0)+IF(S11<'Invités'!$B$91,0,1)+IF(U11>'Invités'!$P$91,2,0)+IF(V11="Non",0,1)+IF(Q11="Oui",1,0)+IF(P11="Non",2,0)+IF(N11>2,2,0)+IF(M11>15000,-2,0)} -> 8 | X11: FALSE
B12: Manoir des Foulons | C12: TRUE | D12: TRUE | E12: TRUE | F12: FALSE | G12: https://www.mariages.net/domaine-mariage/manoir-des-foulons--e8243 | H12: 1 Chemin des Foulons 78790 Rosay (Yvelines) | I12: 55min | J12: 0.92 | K12: 6400 | L12: 2785 | M12: {=_xlfn.IFERROR(K12+L12,50000)} -> 9185 | N12: 3 | O12: du vendredi 17h au dimanche 17h | P12: Non | Q12: Non | R12: 250 | S12: 200 | T12: 13 | U12: 33 | V12: Non | W12: {=IF(J12<2.1,1,0)+IF(M12<'Budget - Budget'!$C$3,2,0)+IF(S12<'Invités'!$B$91,0,1)+IF(U12>'Invités'!$P$91,2,0)+IF(V12="Non",0,1)+IF(Q12="Oui",1,0)+IF(P12="Non",2,0)+IF(N12>2,2,0)+IF(M12>15000,-2,0)} -> 8 | X12: FALSE
B13: Le Domaine de Grisien | C13: TRUE | D13: TRUE | E13: TRUE | F13: FALSE | G13: https://www.mariages.net/domaine-mariage/le-domaine-de-grisien--e381421 | H13: Ferme de Grisien Lieu dit Grisien 77540 Voinsles (Seine-et-Marne) | I13: 1h40 | J13: 1.67 | K13: 8000 | L13: 1500 | M13: {=_xlfn.IFERROR(K13+L13,50000)} -> 9500 | N13: 3 | O13: DU VENDREDI 10H JUSQU’AU DIMANCHE 17H | P13: Non | Q13: Non | R13: 200 | S13: 180 | T13: 14 | U13: 47 | V13: Non | W13: {=IF(J13<2.1,1,0)+IF(M13<'Budget - Budget'!$C$3,2,0)+IF(S13<'Invités'!$B$91,0,1)+IF(U13>'Invités'!$P$91,2,0)+IF(V13="Non",0,1)+IF(Q13="Oui",1,0)+IF(P13="Non",2,0)+IF(N13>2,2,0)+IF(M13>15000,-2,0)} -> 8 | X13: FALSE
B14: Les Jardins de Joséphine | C14: TRUE | D14: TRUE | E14: TRUE | F14: TRUE | G14: https://www.mariages.net/salle-mariage/les-jardins-de-josephine--e152850 | H14: 3, Rue des Quinconces 27000 Évreux (Eure) | I14: 1h20 | J14: 1.33 | K14: 9900 | L14: 0 | M14: {=_xlfn.IFERROR(K14+L14,50000)} -> 9900 | N14: 3 | O14: du vendredi 17h au dimanche 17h | P14: Non | Q14: Non | R14: 250 | S14: 160 | T14: 14 | U14: 31 | V14: Non | W14: {=IF(J14<2.1,1,0)+IF(M14<'Budget - Budget'!$C$3,2,0)+IF(S14<'Invités'!$B$91,0,1)+IF(U14>'Invités'!$P$91,2,0)+IF(V14="Non",0,1)+IF(Q14="Oui",1,0)+IF(P14="Non",2,0)+IF(N14>2,2,0)+IF(M14>15000,-2,0)} -> 8 | X14: TRUE
B15: Domaine de Coulonge | C15: TRUE | D15: TRUE | E15: TRUE | F15: FALSE | G15: https://www.mariages.net/domaine-mariage/domaine-de-coulonge--e195353 | H15: 2, Route de Damville 27240 Sylvains-les-Moulins (Eure) | I15: 1h30 | J15: 1.5 | K15: 6400 | L15: 3502 | M15: {=_xlfn.IFERROR(K15+L15,50000)} -> 9902 | N15: 3 | O15: du vendredi 9h au dimanche 17h | P15: Non | Q15: Non | R15: 380 | S15: 380 | T15: 16 | U15: 48 | V15: Non | W15: {=IF(J15<2.1,1,0)+IF(M15<'Budget - Budget'!$C$3,2,0)+IF(S15<'Invités'!$B$91,0,1)+IF(U15>'Invités'!$P$91,2,0)+IF(V15="Non",0,1)+IF(Q15="Oui",1,0)+IF(P15="Non",2,0)+IF(N15>2,2,0)+IF(M15>15000,-2,0)} -> 8 | X15: FALSE
B16: Le Nomade Lodge | C16: TRUE | D16: TRUE | E16: TRUE | F16: FALSE | G16: https://www.mariages.net/salle-mariage/le-nomade-lodge--e41965 | H16: RD 227 77720 La Chapelle-Gauthier (Seine-et-Marne) | I16: 1h30 | J16: 1.5 | K16: 9010 | L16: {=72*45} -> 3240 | M16: {=_xlfn.IFERROR(K16+L16,50000)} -> 12250 | N16: 3 | O16: DU VENDREDI 10H JUSQU’AU DIMANCHE 18H - pas privatisé mais grand domaine | P16: Non | Q16: Non | R16: 250 | S16: 250 | T16: 70 | U16: 230 | V16: Non | W16: {=IF(J16<2.1,1,0)+IF(M16<'Budget - Budget'!$C$3,2,0)+IF(S16<'Invités'!$B$91,0,1)+IF(U16>'Invités'!$P$91,2,0)+IF(V16="Non",0,1)+IF(Q16="Oui",1,0)+IF(P16="Non",2,0)+IF(N16>2,2,0)+IF(M16>15000,-2,0)} -> 10 | X16: FALSE
B17: La Ferme d'Armenon | C17: TRUE | D17: TRUE | E17: TRUE | F17: TRUE | G17: https://www.mariages.net/domaine-mariage/la-ferme-darmenon--e151906 | H17: Ferme d'Armenon 91470 Les Molières (Essonne) | I17: 55min | J17: 0.92 | K17: 10100 | L17: 4400 | M17: {=_xlfn.IFERROR(K17+L17,50000)} -> 14500 | N17: 3 | O17: (vendredi matin à dimanche 18h) | P17: Non | Q17: Non | R17: 200 | S17: 200 | T17: 19 | U17: 57 | V17: Non | W17: {=IF(J17<2.1,1,0)+IF(M17<'Budget - Budget'!$C$3,2,0)+IF(S17<'Invités'!$B$91,0,1)+IF(U17>'Invités'!$P$91,2,0)+IF(V17="Non",0,1)+IF(Q17="Oui",1,0)+IF(P17="Non",2,0)+IF(N17>2,2,0)+IF(M17>15000,-2,0)} -> 8 | X17: FALSE
B18: La Ferme du Grand Chemin | C18: TRUE | D18: TRUE | E18: FALSE | G18: https://www.mariages.net/domaine-mariage/la-ferme-du-grand-chemin--e102933 | H18: 20, Route de Vétheuil 95510 Vienne-en-Arthies (Val-d'Oise) | I18: 1h | J18: 1 | K18: {=5900+600} -> 6500 | L18: 2428 | M18: {=_xlfn.IFERROR(K18+L18,50000)} -> 8928 | N18: 2 | O18: Samedi au dimanche 16h + traiteur imposé + vendredi que pour installer la déco | P18: Non | Q18: Non | R18: 350 | S18: 350 | T18: 23 | U18: 63 | V18: Non | W18: {=IF(J18<2.1,1,0)+IF(M18<'Budget - Budget'!$C$3,2,0)+IF(S18<'Invités'!$B$91,0,1)+IF(U18>'Invités'!$P$91,2,0)+IF(V18="Non",0,1)+IF(Q18="Oui",1,0)+IF(P18="Non",2,0)+IF(N18>2,2,0)+IF(M18>15000,-2,0)} -> 6 | X18: FALSE
B19: Domaine des Prévanches | C19: TRUE | D19: TRUE | E19: TRUE | F19: FALSE | G19: https://www.mariages.net/domaine-mariage/domaine-des-prevanches--e119212 | H19: centre ville 27120 Boisset-les-Prévanches (Eure) | I19: 1h | J19: 1 | K19: 12700 | L19: 0 | M19: {=_xlfn.IFERROR(K19+L19,50000)} -> 12700 | N19: 3 | O19: du vendredi au dimanche | P19: Non | Q19: Non | R19: 300 | S19: 200 | T19: 25 | U19: 80 | V19: Non | W19: {=IF(J19<2.1,1,0)+IF(M19<'Budget - Budget'!$C$3,2,0)+IF(S19<'Invités'!$B$91,0,1)+IF(U19>'Invités'!$P$91,2,0)+IF(V19="Non",0,1)+IF(Q19="Oui",1,0)+IF(P19="Non",2,0)+IF(N19>2,2,0)+IF(M19>15000,-2,0)} -> 10 | X19: FALSE
B20: Domaine de Bontemps | C20: TRUE | D20: TRUE | E20: TRUE | G20: https://www.mariages.net/domaine-mariage/domaine-de-bontemps--e333446 | H20: Ferme des Aulnoys Bontemps 02310 Domptin (Aisne) | I20: 1h50 | J20: 1.83 | K20: 5500 | L20: 600 | M20: {=_xlfn.IFERROR(K20+L20,50000)} -> 6100 | N20: 3 | O20: Du vendredi 9h à 18h pour l’installation et du samedi 9h au dimanche 18h | P20: Non | Q20: Non | R20: 230 | S20: 230 | T20: 13 | U20: 45 | V20: Non | W20: {=IF(J20<2.1,1,0)+IF(M20<'Budget - Budget'!$C$3,2,0)+IF(S20<'Invités'!$B$91,0,1)+IF(U20>'Invités'!$P$91,2,0)+IF(V20="Non",0,1)+IF(Q20="Oui",1,0)+IF(P20="Non",2,0)+IF(N20>2,2,0)+IF(M20>15000,-2,0)} -> 8 | X20: FALSE
B21: Les Blés Verts | C21: TRUE | D21: TRUE | E21: TRUE | F21: TRUE | G21: https://www.mariages.net/salle-mariage/les-bles-verts--e149476 | H21: 6, Rue de la Grande Ferme 27190 Conches-en-Ouche (Eure) | I21: 1h50 | J21: 1.83 | K21: 3650 | L21: 0 | M21: {=_xlfn.IFERROR(K21+L21,50000)} -> 3650 | N21: 3 | O21: Vendredi 11h00 au dimanche 17h00 | P21: Non | Q21: Non | R21: 120 | S21: 120 | T21: 9 | U21: 35 | V21: Non | W21: {=IF(J21<2.1,1,0)+IF(M21<'Budget - Budget'!$C$3,2,0)+IF(S21<'Invités'!$B$91,0,1)+IF(U21>'Invités'!$P$91,2,0)+IF(V21="Non",0,1)+IF(Q21="Oui",1,0)+IF(P21="Non",2,0)+IF(N21>2,2,0)+IF(M21>15000,-2,0)} -> 8 | X21: FALSE
B22: Domaine de la Croix Sauvalle | C22: TRUE | D22: TRUE | E22: TRUE | F22: FALSE | G22: https://www.mariages.net/domaine-mariage/domaine-de-la-croix-sauvalle--e180437 | H22: 6, Rue de la Croix Sauvalle 27510 Forêt-la-Folie (Eure) | I22: 1h15 | J22: 1.25 | K22: 5300 | L22: {=810+780} -> 1590 | M22: {=_xlfn.IFERROR(K22+L22,50000)} -> 6890 | N22: 3 | O22: Le vendredi 11h00 (pour apporter vos décorations que nous installerons) Et du Samedi 9h00 au Dimanche 16h00 | P22: Non | Q22: Non | R22: 120 | S22: 120 | T22: 5 | U22: 26 | V22: Non | W22: {=IF(J22<2.1,1,0)+IF(M22<'Budget - Budget'!$C$3,2,0)+IF(S22<'Invités'!$B$91,0,1)+IF(U22>'Invités'!$P$91,2,0)+IF(V22="Non",0,1)+IF(Q22="Oui",1,0)+IF(P22="Non",2,0)+IF(N22>2,2,0)+IF(M22>15000,-2,0)} -> 8 | X22: FALSE
B23: Domaine de la Volière | C23: TRUE | D23: TRUE | E23: TRUE | F23: FALSE | G23: https://bridebook.com/fr/wedding-venues/domaine-de-la-voli-re-sainte-maure-de-touraine-indre-et-loire-frBXdAvKg6 | H23: La Volière, Sainte-Maure-de-Touraine, Indre-et-Loire, 37800, Centre-Val de Loire, France | I23: 3h15 | J23: 3.25 | K23: 4370 | L23: 2740 | M23: {=_xlfn.IFERROR(K23+L23,50000)} -> 7110 | N23: 4 | O23: du vendredi 10 h au lundi 10 h | P23: Non | Q23: Non | R23: 350 | S23: 200 | T23: 10 | U23: 30 | V23: Non | W23: {=IF(J23<2.1,1,0)+IF(M23<'Budget - Budget'!$C$3,2,0)+IF(S23<'Invités'!$B$91,0,1)+IF(U23>'Invités'!$P$91,2,0)+IF(V23="Non",0,1)+IF(Q23="Oui",1,0)+IF(P23="Non",2,0)+IF(N23>2,2,0)+IF(M23>15000,-2,0)} -> 7 | X23: FALSE
B24: Pont-Chevron | C24: TRUE | D24: TRUE | E24: TRUE | F24: FALSE | G24: https://bridebook.com/fr/wedding-venues/pont-chevron-ouzouer-sur-tr-z-e-loiret-frm8zlz2gR | H24: Château de Pont-Chevron , Ouzouer-sur-Trézée, Loiret, 45250, Centre-Val de Loire, France | I24: 2h30 | J24: 2.5 | K24: 5700 | L24: 2760 | M24: {=_xlfn.IFERROR(K24+L24,50000)} -> 8460 | N24: 3 | O24: du vendredi 10h au dimanche 14h | P24: Non | Q24: Non | R24: 1200 | S24: 300 | T24: 13 | U24: 44 | V24: Non | W24: {=IF(J24<2.1,1,0)+IF(M24<'Budget - Budget'!$C$3,2,0)+IF(S24<'Invités'!$B$91,0,1)+IF(U24>'Invités'!$P$91,2,0)+IF(V24="Non",0,1)+IF(Q24="Oui",1,0)+IF(P24="Non",2,0)+IF(N24>2,2,0)+IF(M24>15000,-2,0)} -> 7 | X24: FALSE
B25: Château de Laborde Saint-Martin | C25: TRUE | D25: TRUE | E25: TRUE | F25: FALSE | G25: https://bridebook.com/fr/wedding-venues/ch-teau-de-laborde-saint-martin-cand-sur-beuvron-loir-et-cher-frA8xEAaX0 | H25: 53 rue du Château, Candé-sur-Beuvron, Loir-et-Cher, 41120, Centre-Val de Loire, France | I25: 2h45 | J25: 2.75 | K25: 7500 | L25: 2000 | M25: {=_xlfn.IFERROR(K25+L25,50000)} -> 9500 | N25: 3 | O25: vendredi à partir de 15 heures au dimanche 17h | P25: Non | Q25: Non | R25: 280 | S25: 140 | T25: 21 | U25: 42 | V25: Non | W25: {=IF(J25<2.1,1,0)+IF(M25<'Budget - Budget'!$C$3,2,0)+IF(S25<'Invités'!$B$91,0,1)+IF(U25>'Invités'!$P$91,2,0)+IF(V25="Non",0,1)+IF(Q25="Oui",1,0)+IF(P25="Non",2,0)+IF(N25>2,2,0)+IF(M25>15000,-2,0)} -> 7 | X25: FALSE
B26: Manoir de Vacheresses | C26: TRUE | D26: TRUE | E26: TRUE | F26: TRUE | G26: https://www.mariages.net/domaine-mariage/manoir-de-vacheresses--e148581 | H26: Rue du Manoir 28210 Vacheresses-les-Basses (Eure-et-Loir) | I26: 1h15 | J26: 1.25 | K26: 7050 | L26: 2500 | M26: {=_xlfn.IFERROR(K26+L26,50000)} -> 9550 | N26: 3 | O26: du vendredi 14h (préparatifs) au dimanche 17h (brunch) : | P26: Non | Q26: Non | R26: 110 | S26: 110 | T26: 9 | U26: 21 | V26: Non | W26: {=IF(J26<2.1,1,0)+IF(M26<'Budget - Budget'!$C$3,2,0)+IF(S26<'Invités'!$B$91,0,1)+IF(U26>'Invités'!$P$91,2,0)+IF(V26="Non",0,1)+IF(Q26="Oui",1,0)+IF(P26="Non",2,0)+IF(N26>2,2,0)+IF(M26>15000,-2,0)} -> 8 | X26: FALSE
B27: Chateau Hazeville | C27: TRUE | D27: TRUE | E27: TRUE | F27: FALSE | G27: https://bridebook.com/fr/wedding-venues/chateau-hazeville-wy-dit-joli-village-val-d-oise-fr0X22aBQX | H27: Château d'Hazeville, Wy-dit-Joli-Village, Val-d'Oise, 95420, Île-de-France, France | I27: 1h | J27: 1 | K27: 9360 | L27: 810 | M27: {=_xlfn.IFERROR(K27+L27,50000)} -> 10170 | N27: 3 | O27: du vendredi 18h au dimanche 14h | P27: Non | Q27: Non | R27: 160 | S27: 160 | T27: 12 | U27: 45 | V27: Oui | W27: {=IF(J27<2.1,1,0)+IF(M27<'Budget - Budget'!$C$3,2,0)+IF(S27<'Invités'!$B$91,0,1)+IF(U27>'Invités'!$P$91,2,0)+IF(V27="Non",0,1)+IF(Q27="Oui",1,0)+IF(P27="Non",2,0)+IF(N27>2,2,0)+IF(M27>15000,-2,0)} -> 9 | X27: FALSE
B28: Château de Villette | C28: TRUE | D28: TRUE | E28: TRUE | F28: FALSE | G28: https://bridebook.com/fr/wedding-venues/ch-teau-de-villette-sennely-loiret-fr4XD1rLgo | H28: Route de Sennely, Menestreau en Villette, Loiret, 45240, Centre-Val de Loire, France | I28: 2h30 | J28: 2.5 | K28: 7877 | L28: 3106 | M28: {=_xlfn.IFERROR(K28+L28,50000)} -> 10983 | N28: 3 | O28: vendredi 13h au dimanche 19h | P28: Non | Q28: Non | R28: 300 | S28: 300 | T28: 24 | U28: 60 | V28: Non | W28: {=IF(J28<2.1,1,0)+IF(M28<'Budget - Budget'!$C$3,2,0)+IF(S28<'Invités'!$B$91,0,1)+IF(U28>'Invités'!$P$91,2,0)+IF(V28="Non",0,1)+IF(Q28="Oui",1,0)+IF(P28="Non",2,0)+IF(N28>2,2,0)+IF(M28>15000,-2,0)} -> 7 | X28: FALSE
B29: Le Moulin de Pommeuse | C29: TRUE | D29: TRUE | E29: TRUE | F29: FALSE | G29: https://www.mariages.net/domaine-mariage/le-moulin-de-pommeuse--e155990 | H29: 32, avenue du Général Huerne 77515 Pommeuse (Seine-et-Marne) | I29: 1h35 | J29: 1.58 | K29: 5500 | L29: 5530 | M29: {=_xlfn.IFERROR(K29+L29,50000)} -> 11030 | N29: 3 | O29: vendredi 15h au dimanche 18h | P29: Non | Q29: Non | R29: 120 | S29: 100 | T29: 25 | U29: 75 | V29: Non | W29: {=IF(J29<2.1,1,0)+IF(M29<'Budget - Budget'!$C$3,2,0)+IF(S29<'Invités'!$B$91,0,1)+IF(U29>'Invités'!$P$91,2,0)+IF(V29="Non",0,1)+IF(Q29="Oui",1,0)+IF(P29="Non",2,0)+IF(N29>2,2,0)+IF(M29>15000,-2,0)} -> 10 | X29: FALSE
B30: Domaine des Coccinelles | C30: TRUE | D30: TRUE | E30: TRUE | F30: FALSE | G30: https://www.mariages.net/domaine-mariage/domaine-des-coccinelles--e235316 | H30: La Tuilerie 91470 Angervilliers (Essonne) | I30: 1h10 | J30: 1.17 | K30: 13500 | L30: 9120 | M30: {=_xlfn.IFERROR(K30+L30,50000)} -> 22620 | N30: 3 | O30: Vendredi 11h00 au dimanche 17h00 | P30: Non | Q30: Non | R30: 200 | S30: 200 | T30: 16 | U30: 55 | V30: Oui | W30: {=IF(J30<2.1,1,0)+IF(M30<'Budget - Budget'!$C$3,2,0)+IF(S30<'Invités'!$B$91,0,1)+IF(U30>'Invités'!$P$91,2,0)+IF(V30="Non",0,1)+IF(Q30="Oui",1,0)+IF(P30="Non",2,0)+IF(N30>2,2,0)+IF(M30>15000,-2,0)} -> 5 | X30: FALSE
B31: Les Tourelles de Fonville | C31: TRUE | D31: TRUE | E31: TRUE | F31: TRUE | G31: https://www.mariages.net/domaine-mariage/les-tourelles-de-fonville--e185949 | H31: 5, Rue de la Chapelle 28210 Le Boullay-Mivoye (Eure-et-Loir) | I31: 1h15 | J31: 1.25 | K31: 9500 | L31: 0 | M31: {=_xlfn.IFERROR(K31+L31,50000)} -> 9500 | N31: 3 | O31: du vendredi 12h au dimanche 17h | P31: Non | Q31: Non | R31: 130 | S31: 130 | T31: 13 | U31: 36 | V31: Non | W31: {=IF(J31<2.1,1,0)+IF(M31<'Budget - Budget'!$C$3,2,0)+IF(S31<'Invités'!$B$91,0,1)+IF(U31>'Invités'!$P$91,2,0)+IF(V31="Non",0,1)+IF(Q31="Oui",1,0)+IF(P31="Non",2,0)+IF(N31>2,2,0)+IF(M31>15000,-2,0)} -> 8 | X31: FALSE
B32: Domaine de la Thibaudière | C32: TRUE | D32: TRUE | E32: FALSE | G32: https://bridebook.com/fr/shortlist/venues/domaine-de-la-thibaudi-re-faverolles-eure-et-loir-frog49pWYv | H32: Route Du Bout Au Duhay, Faverolles, Eure-et-Loir, 28210, Centre-Val de Loire, France | I32: 1h15 | J32: 1.25 | K32: 22000 | L32: 0 | M32: {=_xlfn.IFERROR(K32+L32,50000)} -> 22000 | N32: 3 | O32: du vendredi 17h00 au dimanche 15h00 | P32: Non | Q32: Non | R32: 180 | S32: 160 | T32: 16 | U32: 56 | V32: Oui | W32: {=IF(J32<2.1,1,0)+IF(M32<'Budget - Budget'!$C$3,2,0)+IF(S32<'Invités'!$B$91,0,1)+IF(U32>'Invités'!$P$91,2,0)+IF(V32="Non",0,1)+IF(Q32="Oui",1,0)+IF(P32="Non",2,0)+IF(N32>2,2,0)+IF(M32>15000,-2,0)} -> 5 | X32: FALSE
B33: Le Clos de l'Orangerie | C33: TRUE | D33: TRUE | E33: FALSE | G33: https://www.mariages.net/domaine-mariage/le-clos-de-lorangerie--e145905 | H33: D110 78710 Rosny-sur-Seine (Yvelines) | I33: 50min | J33: 0.83 | K33: {=65000} -> 65000 | L33: 0 | M33: {=_xlfn.IFERROR(K33+L33,50000)} -> 65000 | N33: 3 | O33: Vendredi 11h00 au dimanche 17h00 (l’hébergement pour 130 personnes, ainsi que la partie technique et le DJ.) | P33: Non | Q33: Non | R33: 400 | S33: 400 | T33: 30 | U33: 60 | V33: Oui | W33: {=IF(J33<2.1,1,0)+IF(M33<'Budget - Budget'!$C$3,2,0)+IF(S33<'Invités'!$B$91,0,1)+IF(U33>'Invités'!$P$91,2,0)+IF(V33="Non",0,1)+IF(Q33="Oui",1,0)+IF(P33="Non",2,0)+IF(N33>2,2,0)+IF(M33>15000,-2,0)} -> 5 | X33: FALSE
B34: L'Orangerie de l’Orée du Bois | C34: TRUE | D34: TRUE | E34: FALSE | G34: https://www.mariages.net/domaine-mariage/lorangerie-de-l-oree-du-bois--e351105 | H34: Chemin de la Côte Blanche 78710 Rosny-sur-Seine (Yvelines) | I34: 55min | J34: 0.92 | K34: {=65000} -> 65000 | L34: 0 | M34: {=_xlfn.IFERROR(K34+L34,50000)} -> 65000 | N34: 3 | O34: Vendredi 11h00 au dimanche 17h00 - plus de disponibilités en 2027 | P34: Non | Q34: Non | R34: 500 | S34: 500 | T34: 23 | U34: 55 | V34: Oui | W34: {=IF(J34<2.1,1,0)+IF(M34<'Budget - Budget'!$C$3,2,0)+IF(S34<'Invités'!$B$91,0,1)+IF(U34>'Invités'!$P$91,2,0)+IF(V34="Non",0,1)+IF(Q34="Oui",1,0)+IF(P34="Non",2,0)+IF(N34>2,2,0)+IF(M34>15000,-2,0)} -> 5 | X34: FALSE
B35: Domaine de Saint Vigor | C35: TRUE | D35: TRUE | E35: TRUE | F35: TRUE | G35: https://www.mariages.net/domaine-mariage/domaine-de-saint-vigor--e194877 | H35: 2, Route des Buissonnets 27930 Saint-Vigor (Eure) | I35: 1h | J35: 2 | K35: 4550 | L35: 4590 | M35: {=_xlfn.IFERROR(K35+L35,50000)} -> 9140 | N35: 3 | O35: Du vendredi 17h au dimanche 17h - traiteur imposé, sinon 600€ droit d’accès | P35: Oui | Q35: Non | R35: 130 | S35: 130 | T35: 14 | U35: 60 | V35: Non | W35: {=IF(J35<2.1,1,0)+IF(M35<'Budget - Budget'!$C$3,2,0)+IF(S35<'Invités'!$B$91,0,1)+IF(U35>'Invités'!$P$91,2,0)+IF(V35="Non",0,1)+IF(Q35="Oui",1,0)+IF(P35="Non",2,0)+IF(N35>2,2,0)+IF(M35>15000,-2,0)} -> 6 | X35: FALSE
B36: Château d'Hermival | C36: TRUE | D36: TRUE | E36: TRUE | F36: FALSE | G36: https://www.mariages.net/chateau-mariage/chateau-dhermival--e194737 | H36: 2686, Route de Cormeilles 14100 Hermival-les-Vaux (Calvados) | I36: 2h10 | J36: 2.17 | K36: 7500 | L36: 750 | M36: {=_xlfn.IFERROR(K36+L36,50000)} -> 8250 | N36: 3 | O36: du vendredi 14h au dimanche 17h | P36: Non | Q36: Non | R36: 120 | S36: 120 | T36: 10 | U36: 38 | V36: Non | W36: {=IF(J36<2.1,1,0)+IF(M36<'Budget - Budget'!$C$3,2,0)+IF(S36<'Invités'!$B$91,0,1)+IF(U36>'Invités'!$P$91,2,0)+IF(V36="Non",0,1)+IF(Q36="Oui",1,0)+IF(P36="Non",2,0)+IF(N36>2,2,0)+IF(M36>15000,-2,0)} -> 7 | X36: FALSE
B37: Domaine de Champignolles | C37: TRUE | D37: TRUE | E37: TRUE | F37: FALSE | G37: https://www.mariages.net/domaine-mariage/domaine-de-champignolles--e329152 | H37: Domaine de champignolles 60590 Sérifontaine (Oise) | I37: 1h20 | J37: 1.33 | K37: 6000 | L37: 4000 | M37: {=_xlfn.IFERROR(K37+L37,50000)} -> 10000 | N37: 4 | O37: du vendredi dès 9h au lundi 10h | P37: Non | Q37: Non | R37: 500 | S37: 500 | T37: 8 | U37: 30 | V37: Non | W37: {=IF(J37<2.1,1,0)+IF(M37<'Budget - Budget'!$C$3,2,0)+IF(S37<'Invités'!$B$91,0,1)+IF(U37>'Invités'!$P$91,2,0)+IF(V37="Non",0,1)+IF(Q37="Oui",1,0)+IF(P37="Non",2,0)+IF(N37>2,2,0)+IF(M37>15000,-2,0)} -> 8 | X37: FALSE
B38: Château de Maudétour | C38: TRUE | D38: TRUE | E38: TRUE | F38: TRUE | G38: https://www.mariages.net/chateau-mariage/chateau-de-maudetour--e137675 | H38: 1, Allée des Tilleuls 95420 Maudétour-en-Vexin (Val-d'Oise) | I38: 55min | J38: 0.92 | K38: 6950 | L38: 5300 | M38: {=_xlfn.IFERROR(K38+L38,50000)} -> 12250 | N38: 3 | O38: du vendredi 17h au dimanche 17h | P38: Non | Q38: Non | R38: 250 | S38: 250 | T38: 19 | U38: 46 | V38: Non | W38: {=IF(J38<2.1,1,0)+IF(M38<'Budget - Budget'!$C$3,2,0)+IF(S38<'Invités'!$B$91,0,1)+IF(U38>'Invités'!$P$91,2,0)+IF(V38="Non",0,1)+IF(Q38="Oui",1,0)+IF(P38="Non",2,0)+IF(N38>2,2,0)+IF(M38>15000,-2,0)} -> 8 | X38: FALSE
B39: Château de Laverdines | C39: TRUE | D39: TRUE | E39: TRUE | F39: FALSE | G39: https://bridebook.com/fr/wedding-venues/ch-teau-de-laverdines-baugy-cher-frqYNwG68V | H39: 2A Route de la Chapelle, Baugy, Cher, 18800, Centre-Val de Loire, France | I39: 3h30 | J39: 3.5 | K39: {=9900+4500} -> 14400 | L39: 0 | M39: {=_xlfn.IFERROR(K39+L39,50000)} -> 14400 | N39: 4 | O39: Vendredi 11h au lundi 17h - attention il faut louer une tente 4,5K€ | P39: Non | Q39: Oui | R39: 250 | S39: 150 | T39: 23 | U39: 42 | V39: Non | W39: {=IF(J39<2.1,1,0)+IF(M39<'Budget - Budget'!$C$3,2,0)+IF(S39<'Invités'!$B$91,0,1)+IF(U39>'Invités'!$P$91,2,0)+IF(V39="Non",0,1)+IF(Q39="Oui",1,0)+IF(P39="Non",2,0)+IF(N39>2,2,0)+IF(M39>15000,-2,0)} -> 8 | X39: FALSE
B40: Château Le Chereau et Domaine Les Poultières | C40: TRUE | D40: TRUE | E40: FALSE | G40: https://bridebook.com/fr/wedding-venues/ch-teau-le-chereau-et-domaine-les-poulti-res-montrieux-en-sologne-loir-et-cher-frEqYZxBX2 | H40: Montrieux-en-Sologne, Loir-et-Cher, Centre-Val de Loire, France | I40: 2h40 | J40: 2.67 | K40: {=12750+5000} -> 17750 | L40: 0 | M40: {=_xlfn.IFERROR(K40+L40,50000)} -> 17750 | N40: 3 | O40: Vendredi (arrivée a midi et plus tôt si possible) jusqu’au Dimanche 16H00 - Que 80 assis en intérieur, pour plus, il faut louer une tente à 5K€ | P40: Non | Q40: Non | R40: 300 | S40: 200 | T40: 25 | U40: 62 | V40: Oui | W40: {=IF(J40<2.1,1,0)+IF(M40<'Budget - Budget'!$C$3,2,0)+IF(S40<'Invités'!$B$91,0,1)+IF(U40>'Invités'!$P$91,2,0)+IF(V40="Non",0,1)+IF(Q40="Oui",1,0)+IF(P40="Non",2,0)+IF(N40>2,2,0)+IF(M40>15000,-2,0)} -> 4 | X40: FALSE
B41: Le Prieuré de Vernelle | C41: TRUE | D41: TRUE | E41: FALSE | G41: https://www.mariages.net/domaine-mariage/le-prieure-de-vernelle--e8151 | H41: Route d'Evry, Lieu dit : Le Prieuré de Vernelle 77166 Grisy-Suisnes (Seine-et-Marne) | I41: 1h30 | J41: 1.5 | K41: 22500 | L41: 0 | M41: {=_xlfn.IFERROR(K41+L41,50000)} -> 22500 | N41: 3 | O41: du vendredi au dimanche | P41: Non | Q41: Non | R41: 200 | S41: 200 | T41: 18 | U41: 65 | V41: Non | W41: {=IF(J41<2.1,1,0)+IF(M41<'Budget - Budget'!$C$3,2,0)+IF(S41<'Invités'!$B$91,0,1)+IF(U41>'Invités'!$P$91,2,0)+IF(V41="Non",0,1)+IF(Q41="Oui",1,0)+IF(P41="Non",2,0)+IF(N41>2,2,0)+IF(M41>15000,-2,0)} -> 4 | X41: FALSE
...

Sheet Repas - Tableau 1
B1: Budget/invité | C1: Budget total | D1: Commentaires | E1: Lien
A2: Repas vendredi soir | B2: {=SUM(B3:B6)} -> 26 | C2: {=SUM(C3:C6)} -> 1190
A3: Food truck - Tartes Flambées | B3: {=C3/45} -> 21 | C3: 945 | D3: De 18h00 à 21h
A4: Eau | B4: {=C4/'Invités'!$L$91} -> 0.51020408 | C4: 25
A5: Bière | B5: {=C5/'Invités'!$L$91} -> 2.4489796 | C5: 120 | D5: Fut 30L
A6: Vin | B6: {=C6/'Invités'!$L$91} -> 2.0408163 | C6: {=10*10} -> 100
A7: Repas samedi midi | B7: {=SUM(B8:B10)} -> 6.6326531 | C7: {=SUM(C8:C10)} -> 325
A8: BBQ | B8: {=C8/'Invités'!$L$91} -> 5.1020408 | C8: 250 | D8: Saucisses/Merguez, Baguettes, Coleslaw, Sauces, Désert
A9: Eau | B9: {=C9/'Invités'!$L$91} -> 0.51020408 | C9: 25
A10: Bière | B10: {=C10/'Invités'!$L$91} -> 1.0204082 | C10: 50
A11: Repas soirée de mariage | B11: {=SUM(B12:B18)} -> 119.82939 | C11: {=SUM(C12:C18)} -> 8867.375
A12: Vin d’honneur | B12: {=C12/'Invités'!$O$91} -> 17.766486 | C12: {='Repas - Gauthier traiteur'!G3+'Repas - Gauthier traiteur'!G20+'Repas - Gauthier traiteur'!G36+'Repas - Gauthier traiteur'!G62} -> 1314.72
A13: Repas | B13: {=C13/'Invités'!$O$91} -> 13.457162 | C13: {='Repas - Gauthier traiteur'!G71+'Repas - Gauthier traiteur'!G84+'Repas - Gauthier traiteur'!G87+'Repas - Gauthier traiteur'!G98+'Repas - Gauthier traiteur'!G120+'Repas - Gauthier traiteur'!G95+'Repas - Gauthier traiteur'!G133} -> 995.83
A14: Fromage | B14: {=C14/'Invités'!$O$91} -> 4.84 | C14: {='Repas - Gauthier traiteur'!G128} -> 358.16
A15: Déssert | B15: {=C15/'Invités'!$O$91} -> 6.325 | C15: {='Repas - Gauthier traiteur'!G137+'Repas - Gauthier traiteur'!G146+'Repas - Gauthier traiteur'!G154} -> 468.05
A16: Pain | B16: {=C16/'Invités'!$O$91} -> 1.1 | C16: {='Repas - Gauthier traiteur'!G159} -> 81.4
A17: Service traiteur | B17: {=C17/'Invités'!$O$91} -> 50.837838 | C17: {='Repas - Gauthier traiteur'!G189} -> 3762
A18: Vaiselle et nappage | B18: {=C18/'Invités'!$O$91} -> 25.502905 | C18: {='Repas - Gauthier traiteur'!G190} -> 1887.215
A19: Boissons repas de mariage | B19: {=SUM(B20:B26)} -> 42.994471 | C19: {=SUM(C20:C26)} -> 2680.72 | D19: Cadeau de 2000€ Hugues
A20: Soft (repas) | B20: {=C20/'Invités'!$O$91} -> 3.52 | C20: {='Repas - Gauthier traiteur'!G162} -> 260.48 | D20: Eau Minérale et Badoit en bouteilles en verre, Coca-Cola et Coca-Cola Zéro, Jus d’orange et jus de pomme, Perrier
A21: Soft (accueil) | B21: {=C21/'Invités'!$R$91} -> 2.135082 | C21: {='Repas - Gauthier traiteur'!G164} -> 130.24 | D21: Eau de Source, Sodas, Perrier, Jus de fruits
A22: Cocktail - Vin d’honneur | B22: {=C22/'Invités'!O$91} -> 0.94594595 | C22: 70 | D22: Cocktail à base de rhum - Fais par Christophe, quel contenant ?
A23: Champagne - Vin d’honneur et Dessert | B23: {=C23/'Invités'!$R$91} -> 29.508197 | C23: {=30*60} -> 1800 | D23: Blanc de Blanc
A24: Vin plat | B24: {=C24/'Invités'!$R$91} -> 1.9672131 | C24: 120
A25: Vin fromage | B25: {=C25/'Invités'!$R$91} -> 0.98360656 | C25: 60
A26: Bière soirée | B26: {=C26/'Invités'!$R$91} -> 3.9344262 | C26: {=120*2} -> 240
A27: Brunch | B27: {=SUM(B28:B33)} -> 43.215373 | C27: {=SUM(C28:C33)} -> 3841.816
A28: Veritable brunch | B28: {=C28/90} -> 19.745 | C28: {='Repas - Gauthier traiteur'!G184} -> 1777.05
A29: Service traiteur | B29: {=C29/90} -> 14.483333 | C29: {=1303.5} -> 1303.5
A30: Vaiselle et nappage | B30: {=C30/90} -> 4.2540667 | C30: {=(67.5+280.56)*1.1} -> 382.866
A31: Soft | B31: {=C31/90} -> 1.76 | C31: {=1.6*1.1*90} -> 158.4
A32: Bière | B32: {=C32/'Invités'!S$91} -> 1.6216216 | C32: 120
A33: Vin rosé | B33: {=C33/'Invités'!S$91} -> 1.3513514 | C33: {=10*10} -> 100
B34: {=B11+B19+B27+B7+B2} -> 238.67189 | C34: {=C11+C19+C27+C7+C2} -> 16904.911

Sheet Repas - Gauthier traiteur
A1: Gauthier traiteur
A2: Articles | B2: Prix unitaire HT | C2: Unité | D2: Quantités | E2: Sélectionner ? | F2: Total HT | G2: Total TTC
A3: COCKTAIL — PIÈCES FROIDES | F3: {=SUM(F4:F19)} -> 523.25 | G3: {=SUM(G4:G19)} -> 575.575
A4: Pièce déco légumes à croquer (200 pcs) + fromage blanc | B4: 125 | C4: pièce | D4: 1 | E4: Oui | F4: {=IF(E4="Oui",B4*D4,0)} -> 125 | G4: {=F4*1.1} -> 137.5
A5: Pièce déco fruits frais + brochettes (200 pcs) | B5: 135 | C5: pièce | D5: 0 | E5: Non | F5: {=IF(E5="Oui",B5*D5,0)} -> 0 | G5: {=F5*1.1} -> 0
A6: Tartines et Fingers (Saint-Jacques, canard, saumon, carotte) | B6: 1 | C6: pièce | D6: 180 | E6: Oui | F6: {=IF(E6="Oui",B6*D6,0)} -> 180 | G6: {=F6*1.1} -> 198
A7: Jolis Légumes (betterave, courgette, carotte) | B7: 1.55 | C7: pièce | D7: 0 | E7: Non | F7: {=IF(E7="Oui",B7*D7,0)} -> 0 | G7: {=F7*1.1} -> 0
A8: Millefeuille saumon fumé maison & mozzarella | B8: 1.3 | C8: pièce | D8: 45 | E8: Oui | F8: {=IF(E8="Oui",B8*D8,0)} -> 58.5 | G8: {=F8*1.1} -> 64.35
A9: Millefeuille de veau vitello Tonnato | B9: 1.3 | C9: pièce | D9: 0 | E9: Non | F9: {=IF(E9="Oui",B9*D9,0)} -> 0 | G9: {=F9*1.1} -> 0
A10: Mi cuit de thon aux sésames et soja | B10: 1.25 | C10: pièce | D10: 45 | E10: Non | F10: {=IF(E10="Oui",B10*D10,0)} -> 0 | G10: {=F10*1.1} -> 0
A11: Tataki de filet de bœuf gravlax | B11: 1.25 | C11: pièce | D11: 45 | E11: Non | F11: {=IF(E11="Oui",B11*D11,0)} -> 0 | G11: {=F11*1.1} -> 0
A12: Club crabe épicé, chou blanc, carottes, pain noir | B12: 1.3 | C12: pièce | D12: 0 | E12: Non | F12: {=IF(E12="Oui",B12*D12,0)} -> 0 | G12: {=F12*1.1} -> 0
A13: Pain aux céréales garnis en surprise (30 pcs) | B13: 28.7 | C13: pièce | D13: 0 | E13: Non | F13: {=IF(E13="Oui",B13*D13,0)} -> 0 | G13: {=F13*1.1} -> 0
A14: Œufs toqués – crème brûlée à la truffe | B14: 1.6 | C14: pièce | D14: 45 | E14: Oui | F14: {=IF(E14="Oui",B14*D14,0)} -> 72 | G14: {=F14*1.1} -> 79.2
A15: Œufs toqués – crème d'œuf et piperade, gressin | B15: 1.5 | C15: pièce | D15: 45 | E15: Non | F15: {=IF(E15="Oui",B15*D15,0)} -> 0 | G15: {=F15*1.1} -> 0
... A19: Gaspacho andalou glacé | B19: 1.35 | C19: pièce | D19: 0 | E19: Non | F19: {=IF(E19="Oui",B19*D19,0)} -> 0 | G19: {=F19*1.1} -> 0
A20: COCKTAIL — PIÈCES CHAUDES | F20: {=SUM(F21:F35)} -> 177.75 | G20: {=SUM(G21:G35)} -> 195.525
A21: Tartes fines et petits chauds (rouget, boudin noir, ris de veau…) | B21: 0.75 | C21: pièce | D21: 90 | E21: Oui | F21: {=IF(E21="Oui",B21*D21,0)} -> 67.5 | G21: {=F21*1.1} -> 74.25
A22: Pastilla de pigeon rôti, confit de fruits de saison | B22: 1.2 | C22: pièce | D22: 0 | E22: Non | F22: {=IF(E22="Oui",B22*D22,0)} -> 0 | G22: {=F22*1.1} -> 0
A23: Pastilla de daurade mi-cuite, chutney agrumes | B23: 1.2 | C23: pièce | D23: 0 | E23: Non | F23: {=IF(E23="Oui",B23*D23,0)} -> 0 | G23: {=F23*1.1} -> 0
A24: Brick de thon aux épices, accras de morue | B24: 1.2 | C24: pièce | D24: 45 | E24: Oui | F24: {=IF(E24="Oui",B24*D24,0)} -> 54 | G24: {=F24*1.1} -> 59.4
A25: Huîtres chaudes, julienne de carottes, curry léger | B25: 1.4 | C25: pièce | D25: 0 | E25: Non | F25: {=IF(E25="Oui",B25*D25,0)} -> 0 | G25: {=F25*1.1} -> 0
A26: Brochettes Saint-Jacques au lard fumé du Perche | B26: 1.95 | C26: pièce | D26: 0 | E26: Non | F26: {=IF(E26="Oui",B26*D26,0)} -> 0 | G26: {=F26*1.1} -> 0
A27: Brochettes croustillantes légumes & cochon du Perche | B27: 1.85 | C27: pièce | D27: 0 | E27: Non | F27: {=IF(E27="Oui",B27*D27,0)} -> 0 | G27: {=F27*1.1} -> 0
A28: Bonbons croustillants au foie gras chaud | B28: 1.65 | C28: pièce | D28: 45 | E28: Non | F28: {=IF(E28="Oui",B28*D28,0)} -> 0 | G28: {=F28*1.1} -> 0
A29: Burger foie gras poêlé & pommes flambées calvados | B29: 1.75 | C29: pièce | D29: 0 | E29: Non | F29: {=IF(E29="Oui",B29*D29,0)} -> 0 | G29: {=F29*1.1} -> 0
A30: Mini Bagels à la provençale | B30: 1.4 | C30: pièce | D30: 0 | E30: Non | F30: {=IF(E30="Oui",B30*D30,0)} -> 0 | G30: {=F30*1.1} -> 0
A31: Briochette aux escargots du Perche | B31: 1.25 | C31: pièce | D31: 45 | E31: Oui | F31: {=IF(E31="Oui",B31*D31,0)} -> 56.25 | G31: {=F31*1.1} -> 61.875
A32: Pipette de jus de cassis, cromesquis bleu & noix | B32: 1.25 | C32: pièce | D32: 0 | E32: Non | F32: {=IF(E32="Oui",B32*D32,0)} -> 0 | G32: {=F32*1.1} -> 0
... A35: Cuillère filet de rouget tiède, huile de persil, pickles | B35: 1.85 | C35: pièce | D35: 0 | E35: Non | F35: {=IF(E35="Oui",B35*D35,0)} -> 0 | G35: {=F35*1.1} -> 0
